2024-05-13 23:02:21,823 FILE: creds.py IN: create_new_token MESSAGE: Ошибка получения iam_token: HTTPConnectionPool(host='169.254.169.254', port=80): Max retries exceeded with url: /computeMetadata/v1/instance/service-accounts/default/token (Caused by NewConnectionError('<urllib3.connection.HTTPConnection object at 0x0000024C01882F40>: Failed to establish a new connection: [WinError 10051] Сделана попытка выполнить операцию на сокете при отключенной сети'))
2024-05-13 23:02:21,829 FILE: creds.py IN: create_new_token MESSAGE: Ошибка получения iam_token: HTTPConnectionPool(host='169.254.169.254', port=80): Max retries exceeded with url: /computeMetadata/v1/instance/service-accounts/default/token (Caused by NewConnectionError('<urllib3.connection.HTTPConnection object at 0x0000024C01881550>: Failed to establish a new connection: [WinError 10051] Сделана попытка выполнить операцию на сокете при отключенной сети'))
2024-05-13 23:02:21,831 FILE: database.py IN: create_database MESSAGE: DATABASE: База данных создана
